Workbook

Sheet README
A1: US Fine Jewelry Repair Price & Turnaround Catalog
A2: Seed data for the repair-desk estimate engine. Prepared 3 Oct 2026.
A4: What this is
A5: Typical US retail customer prices for common fine-jewelry repairs, by metal (14K, 18K, platinum), with low / typical / high ranges and turnaround for in-house bench vs sent out.
A7: How it was built
A8: 1. 14K low / typical / high prices are inputs (blue), synthesized from published US jeweler price lists (see Sources tab). Typical leans on the most complete list (S1) and is cross-checked against the others.
A9: 2. 18K and platinum prices are formulas: 14K price x metal multiplier from the Assumptions tab. Each service carries a metal class: L (labor only), P (partial metal), H (heavy metal, e.g. sizing up, shanks).
A10: 3. Pricing logic follows the method David Geller teaches (Geller's Blue Book): labor priced per task plus materials marked up about 3x cost, so metal-heavy jobs scale with metal type and spot price (S9). Geller's Blue Book itself is a paid, copyrighted guide; its price tables are NOT reproduced here.
A11: 4. Turnaround is in business days, from public jeweler and mail-in repair guidance (S6 to S8) plus typical bench practice. Sent-out includes transit to a trade shop or central hub.
A13: Tabs
A14: Assumptions: metal multipliers and add-on fees. Edit the yellow cells to re-price the whole catalog.
A15: Service Catalog: 70 services with codes, price drivers, prices by metal, turnaround, and an intake capture checklist for the AI.
... A23: Prices are independent-jeweler retail benchmarks, 2020 to 2025 lists, not chain-specific. Chains often discount sizing at purchase and clean for free. Gold and platinum spot prices move metal-heavy jobs most (sizing up, shanks). Validate with 2 to 3 chains' actual repair price books during discovery before using in production.

Sheet Assumptions
A1: Assumptions
A2: Metal multipliers applied to 14K prices. Yellow cells are the levers to validate.
A4: Class | B4: Description | C4: 14K | D4: 18K | E4: Platinum | F4: Basis / source
A5: L | B5: Labor only: polishing, tightening, plating, restringing, engraving | C5: 1 | D5: 1 | E5: 1.2 | F5: S5: platinum polish and tightening $60 vs $50 gold (+20%). 18K labor same as 14K.
A6: P | B6: Partial metal: prongs, solder joints, heads, clasps, posts, chain work | C6: 1 | D6: 1.15 | E6: 2 | F6: Judgment between S5 (platinum solder +17%) and S1 (platinum solder 3x). Platinum needs higher heat, separate tools, more finishing time. Validate.
A7: H | B7: Heavy metal: sizing up, shanks, sizing beads, butterfly inserts | C7: 1 | D7: 1.2 | E7: 3 | F7: S1: 18K add 20%, platinum triple for sizing and shanks. S9: material marked up ~3x cost.
A9: Add-on fees
A10: White gold re-rhodium after bench work (per item) | C10: 10 | F10: S1: white gold + rhodium $10 extra on sizing
A11: Rush fee (per job) | C11: 50 | F11: S1: rush job $50
A12: Fancy-shape stone uplift (setting / head jobs) | C12: 0.15 | F12: S1: fancy shapes +15%
A13: Bezel setting uplift | C13: 0.2 | F13: S1: bezels add 20%
A14: Stone sourcing adds to turnaround (business days, max) | C14: 20 | F14: S6: stone sourcing up to four weeks

Sheet Service Catalog
A1: Service Catalog: US fine jewelry repair, retail prices and turnaround
A2: Prices in USD, retail to customer. 14K values are inputs (blue); 18K and platinum are formulas off the Assumptions tab. Turnaround in business days.
A3: Service | G3: 14K price ($) | J3: 18K price ($) | M3: Platinum price ($) | P3: Add-on | Q3: In-house bench (days) | S3: Sent out (days) | U3: Engine fields
A4: Code | B4: Category | C4: Service | D4: Unit | E4: Price driver | F4: Metal class | G4: Low | H4: Typical | I4: High | J4: Low | K4: Typical | L4: High | M4: Low | N4: Typical | O4: High | P4: Each add'l unit (14K typ) | Q4: Min | R4: Max | S4: Min | T4: Max | U4: Same-day eligible | V4: Intake capture checklist (for AI) | W4: Sources
A5: SZ-01 | B5: Sizing | C5: Size down, ladies band up to 3mm | D5: per ring | E5: Width, sizes down, stones in shank | F5: H | G5: 40 | H5: 60 | I5: 90 | J5: =G5*INDEX(Assumptions!$D$5:$D$7,MATCH($F5,Assumptions!$A$5:$A$7,0)) -> 48 | K5: =H5*INDEX(Assumptions!$D$5:$D$7,MATCH($F5,Assumptions!$A$5:$A$7,0)) -> 72 | L5: =I5*INDEX(Assumptions!$D$5:$D$7,MATCH($F5,Assumptions!$A$5:$A$7,0)) -> 108 | M5: =G5*INDEX(Assumptions!$E$5:$E$7,MATCH($F5,Assumptions!$A$5:$A$7,0)) -> 120 | N5: =H5*INDEX(Assumptions!$E$5:$E$7,MATCH($F5,Assumptions!$A$5:$A$7,0)) -> 180 | O5: =I5*INDEX(Assumptions!$E$5:$E$7,MATCH($F5,Assumptions!$A$5:$A$7,0)) -> 270 | Q5: 0 | R5: 3 | S5: 5 | T5: 10 | U5: Yes | V5: Photo: inside shank (karat stamp, existing solder seams), top view. Record current and target size, band width (mm), stones in shank, engraving to protect. | W5: S1,S2,S3,S4,S5
A6: SZ-02 | B6: Sizing | C6: Size up 1 size, ladies band up to 3mm | D6: per ring | E6: Width, sizes up (add'l per size) | F6: H | G6: 50 | H6: 70 | I6: 110 | J6: =G6*INDEX(Assumptions!$D$5:$D$7,MATCH($F6,Assumptions!$A$5:$A$7,0)) -> 60 | K6: =H6*INDEX(Assumptions!$D$5:$D$7,MATCH($F6,Assumptions!$A$5:$A$7,0)) -> 84 | L6: =I6*INDEX(Assumptions!$D$5:$D$7,MATCH($F6,Assumptions!$A$5:$A$7,0)) -> 132 | M6: =G6*INDEX(Assumptions!$E$5:$E$7,MATCH($F6,Assumptions!$A$5:$A$7,0)) -> 150 | N6: =H6*INDEX(Assumptions!$E$5:$E$7,MATCH($F6,Assumptions!$A$5:$A$7,0)) -> 210 | O6: =I6*INDEX(Assumptions!$E$5:$E$7,MATCH($F6,Assumptions!$A$5:$A$7,0)) -> 330 | P6: 15 | Q6: 0 | R6: 3 | S6: 5 | T6: 10 | U6: Yes | V6: Photo: inside shank (karat stamp, existing solder seams), top view. Record current and target size, band width (mm), stones in shank, engraving to protect. | W6: S1,S2,S4
A7: SZ-03 | B7: Sizing | C7: Size down, gents / wide band over 3mm | D7: per ring | E7: Width, profile (comfort fit adds time) | F7: H | G7: 55 | H7: 70 | I7: 120 | J7: =G7*INDEX(Assumptions!$D$5:$D$7,MATCH($F7,Assumptions!$A$5:$A$7,0)) -> 66 | K7: =H7*INDEX(Assumptions!$D$5:$D$7,MATCH($F7,Assumptions!$A$5:$A$7,0)) -> 84 | L7: =I7*INDEX(Assumptions!$D$5:$D$7,MATCH($F7,Assumptions!$A$5:$A$7,0)) -> 144 | M7: =G7*INDEX(Assumptions!$E$5:$E$7,MATCH($F7,Assumptions!$A$5:$A$7,0)) -> 165 | N7: =H7*INDEX(Assumptions!$E$5:$E$7,MATCH($F7,Assumptions!$A$5:$A$7,0)) -> 210 | O7: =I7*INDEX(Assumptions!$E$5:$E$7,MATCH($F7,Assumptions!$A$5:$A$7,0)) -> 360 | Q7: 1 | R7: 3 | S7: 5 | T7: 10 | U7: Yes | V7: Photo: inside shank (karat stamp, existing solder seams), top view. Record current and target size, band width (mm), stones in shank, engraving to protect. | W7: S1,S4
A8: SZ-04 | B8: Sizing | C8: Size up 1 size, gents / wide band over 3mm | D8: per ring | E8: Width, sizes up (add'l per size) | F8: H | G8: 70 | H8: 90 | I8: 150 | J8: =G8*INDEX(Assumptions!$D$5:$D$7,MATCH($F8,Assumptions!$A$5:$A$7,0)) -> 84 | K8: =H8*INDEX(Assumptions!$D$5:$D$7,MATCH($F8,Assumptions!$A$5:$A$7,0)) -> 108 | L8: =I8*INDEX(Assumptions!$D$5:$D$7,MATCH($F8,Assumptions!$A$5:$A$7,0)) -> 180 | M8: =G8*INDEX(Assumptions!$E$5:$E$7,MATCH($F8,Assumptions!$A$5:$A$7,0)) -> 210 | N8: =H8*INDEX(Assumptions!$E$5:$E$7,MATCH($F8,Assumptions!$A$5:$A$7,0)) -> 270 | O8: =I8*INDEX(Assumptions!$E$5:$E$7,MATCH($F8,Assumptions!$A$5:$A$7,0)) -> 450 | P8: 20 | Q8: 1 | R8: 5 | S8: 7 | T8: 10 | U8: No | V8: Photo: inside shank (karat stamp, existing solder seams), top view. Record current and target size, band width (mm), stones in shank, engraving to protect. | W8: S1,S4
A9: SZ-05 | B9: Sizing | C9: Sizing with channel / pave / eternity stones in shank | D9: per ring | E9: Stone count in shank, stone re-tightening | F9: H | G9: 120 | H9: 175 | I9: 400 | J9: =G9*INDEX(Assumptions!$D$5:$D$7,MATCH($F9,Assumptions!$A$5:$A$7,0)) -> 144 | K9: =H9*INDEX(Assumptions!$D$5:$D$7,MATCH($F9,Assumptions!$A$5:$A$7,0)) -> 210 | L9: =I9*INDEX(Assumptions!$D$5:$D$7,MATCH($F9,Assumptions!$A$5:$A$7,0)) -> 480 | M9: =G9*INDEX(Assumptions!$E$5:$E$7,MATCH($F9,Assumptions!$A$5:$A$7,0)) -> 360 | N9: =H9*INDEX(Assumptions!$E$5:$E$7,MATCH($F9,Assumptions!$A$5:$A$7,0)) -> 525 | O9: =I9*INDEX(Assumptions!$E$5:$E$7,MATCH($F9,Assumptions!$A$5:$A$7,0)) -> 1200 | Q9: 3 | R9: 7 | S9: 10 | T9: 15 | U9: No | V9: Photo: inside shank (karat stamp, existing solder seams), top view. Record current and target size, band width (mm), stones in shank, engraving to protect. | W9: S4
A10: SZ-06 | B10: Sizing | C10: Sizing beads / bumps (pair) | D10: per ring | E10: Bead size | F10: P | G10: 45 | H10: 80 | I10: 150 | J10: =G10*INDEX(Assumptions!$D$5:$D$7,MATCH($F10,Assumptions!$A$5:$A$7,0)) -> 51.75 | K10: =H10*INDEX(Assumptions!$D$5:$D$7,MATCH($F10,Assumptions!$A$5:$A$7,0)) -> 92 | L10: =I10*INDEX(Assumptions!$D$5:$D$7,MATCH($F10,Assumptions!$A$5:$A$7,0)) -> 172.5 | M10: =G10*INDEX(Assumptions!$E$5:$E$7,MATCH($F10,Assumptions!$A$5:$A$7,0)) -> 90 | N10: =H10*INDEX(Assumptions!$E$5:$E$7,MATCH($F10,Assumptions!$A$5:$A$7,0)) -> 160 | O10: =I10*INDEX(Assumptions!$E$5:$E$7,MATCH($F10,Assumptions!$A$5:$A$7,0)) -> 300 | Q10: 0 | R10: 2 | S10: 5 | T10: 7 | U10: Yes | V10: Photo: inside shank (karat stamp, existing solder seams), top view. Record current and target size, band width (mm), stones in shank, engraving to protect. | W10: S1,S2
A11: SZ-07 | B11: Sizing | C11: Spring / butterfly sizing insert | D11: per ring | E11: Shank width | F11: H | G11: 60 | H11: 90 | I11: 120 | J11: =G11*INDEX(Assumptions!$D$5:$D$7,MATCH($F11,Assumptions!$A$5:$A$7,0)) -> 72 | K11: =H11*INDEX(Assumptions!$D$5:$D$7,MATCH($F11,Assumptions!$A$5:$A$7,0)) -> 108 | L11: =I11*INDEX(Assumptions!$D$5:$D$7,MATCH($F11,Assumptions!$A$5:$A$7,0)) -> 144 | M11: =G11*INDEX(Assumptions!$E$5:$E$7,MATCH($F11,Assumptions!$A$5:$A$7,0)) -> 180 | N11: =H11*INDEX(Assumptions!$E$5:$E$7,MATCH($F11,Assumptions!$A$5:$A$7,0)) -> 270 | O11: =I11*INDEX(Assumptions!$E$5:$E$7,MATCH($F11,Assumptions!$A$5:$A$7,0)) -> 360 | Q11: 1 | R11: 3 | S11: 5 | T11: 10 | U11: No | V11: Photo: inside shank (karat stamp, existing solder seams), top view. Record current and target size, band width (mm), stones in shank, engraving to protect. | W11: S1
A12: SZ-08 | B12: Sizing | C12: Emergency ring removal (cut off) | D12: per ring | E12: Metal hardness (platinum, tungsten) | F12: L | G12: 20 | H12: 30 | I12: 50 | J12: =G12*INDEX(Assumptions!$D$5:$D$7,MATCH($F12,Assumptions!$A$5:$A$7,0)) -> 20 | K12: =H12*INDEX(Assumptions!$D$5:$D$7,MATCH($F12,Assumptions!$A$5:$A$7,0)) -> 30 | L12: =I12*INDEX(Assumptions!$D$5:$D$7,MATCH($F12,Assumptions!$A$5:$A$7,0)) -> 50 | M12: =G12*INDEX(Assumptions!$E$5:$E$7,MATCH($F12,Assumptions!$A$5:$A$7,0)) -> 24 | N12: =H12*INDEX(Assumptions!$E$5:$E$7,MATCH($F12,Assumptions!$A$5:$A$7,0)) -> 36 | O12: =I12*INDEX(Assumptions!$E$5:$E$7,MATCH($F12,Assumptions!$A$5:$A$7,0)) -> 60 | Q12: 0 | R12: 0 | U12: Yes | V12: Photo: inside shank (karat stamp, existing solder seams), top view. Record current and target size, band width (mm), stones in shank, engraving to protect. | W12: S6
A13: SH-01 | B13: Shank | C13: Quarter shank replacement, up to 3mm | D13: per ring | E13: Width, profile | F13: H | G13: 120 | H13: 150 | I13: 200 | J13: =G13*INDEX(Assumptions!$D$5:$D$7,MATCH($F13,Assumptions!$A$5:$A$7,0)) -> 144 | K13: =H13*INDEX(Assumptions!$D$5:$D$7,MATCH($F13,Assumptions!$A$5:$A$7,0)) -> 180 | L13: =I13*INDEX(Assumptions!$D$5:$D$7,MATCH($F13,Assumptions!$A$5:$A$7,0)) -> 240 | M13: =G13*INDEX(Assumptions!$E$5:$E$7,MATCH($F13,Assumptions!$A$5:$A$7,0)) -> 360 | N13: =H13*INDEX(Assumptions!$E$5:$E$7,MATCH($F13,Assumptions!$A$5:$A$7,0)) -> 450 | O13: =I13*INDEX(Assumptions!$E$5:$E$7,MATCH($F13,Assumptions!$A$5:$A$7,0)) -> 600 | Q13: 2 | R13: 5 | S13: 7 | T13: 15 | U13: No | V13: Photo: thinnest point of shank with caliper reading (mm), any cracks, top view. Record width, metal, stones near repair area. | W13: S1,S4
A14: SH-02 | B14: Shank | C14: Half shank replacement, up to 3mm | D14: per ring | E14: Width, profile | F14: H | G14: 150 | H14: 200 | I14: 275 | J14: =G14*INDEX(Assumptions!$D$5:$D$7,MATCH($F14,Assumptions!$A$5:$A$7,0)) -> 180 | K14: =H14*INDEX(Assumptions!$D$5:$D$7,MATCH($F14,Assumptions!$A$5:$A$7,0)) -> 240 | L14: =I14*INDEX(Assumptions!$D$5:$D$7,MATCH($F14,Assumptions!$A$5:$A$7,0)) -> 330 | M14: =G14*INDEX(Assumptions!$E$5:$E$7,MATCH($F14,Assumptions!$A$5:$A$7,0)) -> 450 | N14: =H14*INDEX(Assumptions!$E$5:$E$7,MATCH($F14,Assumptions!$A$5:$A$7,0)) -> 600 | O14: =I14*INDEX(Assumptions!$E$5:$E$7,MATCH($F14,Assumptions!$A$5:$A$7,0)) -> 825 | Q14: 2 | R14: 5 | S14: 7 | T14: 15 | U14: No | V14: Photo: thinnest point of shank with caliper reading (mm), any cracks, top view. Record width, metal, stones near repair area. | W14: S1,S2,S4
A15: SH-03 | B15: Shank | C15: Half shank replacement, 3 to 5mm | D15: per ring | E15: Width, profile | F15: H | G15: 225 | H15: 300 | I15: 400 | J15: =G15*INDEX(Assumptions!$D$5:$D$7,MATCH($F15,Assumptions!$A$5:$A$7,0)) -> 270 | K15: =H15*INDEX(Assumptions!$D$5:$D$7,MATCH($F15,Assumptions!$A$5:$A$7,0)) -> 360 | L15: =I15*INDEX(Assumptions!$D$5:$D$7,MATCH($F15,Assumptions!$A$5:$A$7,0)) -> 480 | M15: =G15*INDEX(Assumptions!$E$5:$E$7,MATCH($F15,Assumptions!$A$5:$A$7,0)) -> 675 | N15: =H15*INDEX(Assumptions!$E$5:$E$7,MATCH($F15,Assumptions!$A$5:$A$7,0)) -> 900 | O15: =I15*INDEX(Assumptions!$E$5:$E$7,MATCH($F15,Assumptions!$A$5:$A$7,0)) -> 1200 | Q15: 2 | R15: 5 | S15: 7 | T15: 15 | U15: No | V15: Photo: thinnest point of shank with caliper reading (mm), any cracks, top view. Record width, metal, stones near repair area. | W15: S1,S4
A16: SH-04 | B16: Shank | C16: Half shank replacement, 6 to 8mm | D16: per ring | E16: Width, profile | F16: H | G16: 300 | H16: 400 | I16: 550 | J16: =G16*INDEX(Assumptions!$D$5:$D$7,MATCH($F16,Assumptions!$A$5:$A$7,0)) -> 360 | K16: =H16*INDEX(Assumptions!$D$5:$D$7,MATCH($F16,Assumptions!$A$5:$A$7,0)) -> 480 | L16: =I16*INDEX(Assumptions!$D$5:$D$7,MATCH($F16,Assumptions!$A$5:$A$7,0)) -> 660 | M16: =G16*INDEX(Assumptions!$E$5:$E$7,MATCH($F16,Assumptions!$A$5:$A$7,0)) -> 900 | N16: =H16*INDEX(Assumptions!$E$5:$E$7,MATCH($F16,Assumptions!$A$5:$A$7,0)) -> 1200 | O16: =I16*INDEX(Assumptions!$E$5:$E$7,MATCH($F16,Assumptions!$A$5:$A$7,0)) -> 1650 | Q16: 3 | R16: 7 | S16: 10 | T16: 15 | U16: No | V16: Photo: thinnest point of shank with caliper reading (mm), any cracks, top view. Record width, metal, stones near repair area. | W16: S1
A17: SH-05 | B17: Shank | C17: Three-quarter shank replacement, up to 3mm | D17: per ring | E17: Width, profile | F17: H | G17: 200 | H17: 250 | I17: 350 | J17: =G17*INDEX(Assumptions!$D$5:$D$7,MATCH($F17,Assumptions!$A$5:$A$7,0)) -> 240 | K17: =H17*INDEX(Assumptions!$D$5:$D$7,MATCH($F17,Assumptions!$A$5:$A$7,0)) -> 300 | L17: =I17*INDEX(Assumptions!$D$5:$D$7,MATCH($F17,Assumptions!$A$5:$A$7,0)) -> 420 | M17: =G17*INDEX(Assumptions!$E$5:$E$7,MATCH($F17,Assumptions!$A$5:$A$7,0)) -> 600 | N17: =H17*INDEX(Assumptions!$E$5:$E$7,MATCH($F17,Assumptions!$A$5:$A$7,0)) -> 750 | O17: =I17*INDEX(Assumptions!$E$5:$E$7,MATCH($F17,Assumptions!$A$5:$A$7,0)) -> 1050 | Q17: 2 | R17: 5 | S17: 7 | T17: 15 | U17: No | V17: Photo: thinnest point of shank with caliper reading (mm), any cracks, top view. Record width, metal, stones near repair area. | W17: S1
A18: SH-06 | B18: Shank | C18: Full shank / reshank, 3 to 5mm | D18: per ring | E18: Width, stones in shank | F18: H | G18: 250 | H18: 350 | I18: 500 | J18: =G18*INDEX(Assumptions!$D$5:$D$7,MATCH($F18,Assumptions!$A$5:$A$7,0)) -> 300 | K18: =H18*INDEX(Assumptions!$D$5:$D$7,MATCH($F18,Assumptions!$A$5:$A$7,0)) -> 420 | L18: =I18*INDEX(Assumptions!$D$5:$D$7,MATCH($F18,Assumptions!$A$5:$A$7,0)) -> 600 | M18: =G18*INDEX(Assumptions!$E$5:$E$7,MATCH($F18,Assumptions!$A$5:$A$7,0)) -> 750 | N18: =H18*INDEX(Assumptions!$E$5:$E$7,MATCH($F18,Assumptions!$A$5:$A$7,0)) -> 1050 | O18: =I18*INDEX(Assumptions!$E$5:$E$7,MATCH($F18,Assumptions!$A$5:$A$7,0)) -> 1500 | Q18: 3 | R18: 7 | S18: 10 | T18: 15 | U18: No | V18: Photo: thinnest point of shank with caliper reading (mm), any cracks, top view. Record width, metal, stones near repair area. | W18: S2,S4
A19: SH-07 | B19: Shank | C19: Solder break in shank | D19: per ring | E19: Location of break, stones near joint | F19: P | G19: 44 | H19: 60 | I19: 175 | J19: =G19*INDEX(Assumptions!$D$5:$D$7,MATCH($F19,Assumptions!$A$5:$A$7,0)) -> 50.6 | K19: =H19*INDEX(Assumptions!$D$5:$D$7,MATCH($F19,Assumptions!$A$5:$A$7,0)) -> 69 | L19: =I19*INDEX(Assumptions!$D$5:$D$7,MATCH($F19,Assumptions!$A$5:$A$7,0)) -> 201.25 | M19: =G19*INDEX(Assumptions!$E$5:$E$7,MATCH($F19,Assumptions!$A$5:$A$7,0)) -> 88 | N19: =H19*INDEX(Assumptions!$E$5:$E$7,MATCH($F19,Assumptions!$A$5:$A$7,0)) -> 120 | O19: =I19*INDEX(Assumptions!$E$5:$E$7,MATCH($F19,Assumptions!$A$5:$A$7,0)) -> 350 | Q19: 0 | R19: 2 | S19: 5 | T19: 10 | U19: Yes | V19: Photo: thinnest point of shank with caliper reading (mm), any cracks, top view. Record width, metal, stones near repair area. | W19: S1,S2,S4
A20: SH-08 | B20: Shank | C20: Solder 2 rings together (wedding set) | D20: per set | E20: Ring widths | F20: P | G20: 74 | H20: 85 | I20: 120 | J20: =G20*INDEX(Assumptions!$D$5:$D$7,MATCH($F20,Assumptions!$A$5:$A$7,0)) -> 85.1 | K20: =H20*INDEX(Assumptions!$D$5:$D$7,MATCH($F20,Assumptions!$A$5:$A$7,0)) -> 97.75 | L20: =I20*INDEX(Assumptions!$D$5:$D$7,MATCH($F20,Assumptions!$A$5:$A$7,0)) -> 138 | M20: =G20*INDEX(Assumptions!$E$5:$E$7,MATCH($F20,Assumptions!$A$5:$A$7,0)) -> 148 | N20: =H20*INDEX(Assumptions!$E$5:$E$7,MATCH($F20,Assumptions!$A$5:$A$7,0)) -> 170 | O20: =I20*INDEX(Assumptions!$E$5:$E$7,MATCH($F20,Assumptions!$A$5:$A$7,0)) -> 240 | Q20: 0 | R20: 2 | S20: 5 | T20: 10 | U20: Yes | V20: Photo: thinnest point of shank with caliper reading (mm), any cracks, top view. Record width, metal, stones near repair area. | W20: S1,S2,S5
A21: SH-09 | B21: Shank | C21: Solder 3 rings together | D21: per set | E21: Ring widths | F21: P | G21: 110 | H21: 120 | I21: 180 | J21: =G21*INDEX(Assumptions!$D$5:$D$7,MATCH($F21,Assumptions!$A$5:$A$7,0)) -> 126.5 | K21: =H21*INDEX(Assumptions!$D$5:$D$7,MATCH($F21,Assumptions!$A$5:$A$7,0)) -> 138 | L21: =I21*INDEX(Assumptions!$D$5:$D$7,MATCH($F21,Assumptions!$A$5:$A$7,0)) -> 207 | M21: =G21*INDEX(Assumptions!$E$5:$E$7,MATCH($F21,Assumptions!$A$5:$A$7,0)) -> 220 | N21: =H21*INDEX(Assumptions!$E$5:$E$7,MATCH($F21,Assumptions!$A$5:$A$7,0)) -> 240 | O21: =I21*INDEX(Assumptions!$E$5:$E$7,MATCH($F21,Assumptions!$A$5:$A$7,0)) -> 360 | Q21: 1 | R21: 3 | S21: 5 | T21: 10 | U21: No | V21: Photo: thinnest point of shank with caliper reading (mm), any cracks, top view. Record width, metal, stones near repair area. | W21: S1,S5
A22: SH-10 | B22: Shank | C22: Cut soldered rings apart and refinish | D22: per set | E22: Number of joints | F22: L | G22: 75 | H22: 100 | I22: 140 | J22: =G22*INDEX(Assumptions!$D$5:$D$7,MATCH($F22,Assumptions!$A$5:$A$7,0)) -> 75 | K22: =H22*INDEX(Assumptions!$D$5:$D$7,MATCH($F22,Assumptions!$A$5:$A$7,0)) -> 100 | L22: =I22*INDEX(Assumptions!$D$5:$D$7,MATCH($F22,Assumptions!$A$5:$A$7,0)) -> 140 | M22: =G22*INDEX(Assumptions!$E$5:$E$7,MATCH($F22,Assumptions!$A$5:$A$7,0)) -> 90 | N22: =H22*INDEX(Assumptions!$E$5:$E$7,MATCH($F22,Assumptions!$A$5:$A$7,0)) -> 120 | O22: =I22*INDEX(Assumptions!$E$5:$E$7,MATCH($F22,Assumptions!$A$5:$A$7,0)) -> 168 | Q22: 0 | R22: 2 | S22: 5 | T22: 10 | U22: Yes | V22: Photo: thinnest point of shank with caliper reading (mm), any cracks, top view. Record width, metal, stones near repair area. | W22: S1
A23: SH-11 | B23: Shank | C23: Reshape out-of-round / bent band and refinish | D23: per ring | E23: Severity | F23: L | G23: 40 | H23: 75 | I23: 150 | J23: =G23*INDEX(Assumptions!$D$5:$D$7,MATCH($F23,Assumptions!$A$5:$A$7,0)) -> 40 | K23: =H23*INDEX(Assumptions!$D$5:$D$7,MATCH($F23,Assumptions!$A$5:$A$7,0)) -> 75 | L23: =I23*INDEX(Assumptions!$D$5:$D$7,MATCH($F23,Assumptions!$A$5:$A$7,0)) -> 150 | M23: =G23*INDEX(Assumptions!$E$5:$E$7,MATCH($F23,Assumptions!$A$5:$A$7,0)) -> 48 | N23: =H23*INDEX(Assumptions!$E$5:$E$7,MATCH($F23,Assumptions!$A$5:$A$7,0)) -> 90 | O23: =I23*INDEX(Assumptions!$E$5:$E$7,MATCH($F23,Assumptions!$A$5:$A$7,0)) -> 180 | Q23: 0 | R23: 2 | S23: 5 | T23: 10 | U23: Yes | V23: Photo: thinnest point of shank with caliper reading (mm), any cracks, top view. Record width, metal, stones near repair area. | W23: S1,S5
A24: SH-12 | B24: Shank | C24: Interior guard / reinforcement plate | D24: per ring | E24: Width, length | F24: H | G24: 100 | H24: 150 | I24: 250 | J24: =G24*INDEX(Assumptions!$D$5:$D$7,MATCH($F24,Assumptions!$A$5:$A$7,0)) -> 120 | K24: =H24*INDEX(Assumptions!$D$5:$D$7,MATCH($F24,Assumptions!$A$5:$A$7,0)) -> 180 | L24: =I24*INDEX(Assumptions!$D$5:$D$7,MATCH($F24,Assumptions!$A$5:$A$7,0)) -> 300 | M24: =G24*INDEX(Assumptions!$E$5:$E$7,MATCH($F24,Assumptions!$A$5:$A$7,0)) -> 300 | N24: =H24*INDEX(Assumptions!$E$5:$E$7,MATCH($F24,Assumptions!$A$5:$A$7,0)) -> 450 | O24: =I24*INDEX(Assumptions!$E$5:$E$7,MATCH($F24,Assumptions!$A$5:$A$7,0)) -> 750 | Q24: 2 | R24: 5 | S24: 7 | T24: 15 | U24: No | V24: Photo: thinnest point of shank with caliper reading (mm), any cracks, top view. Record width, metal, stones near repair area. | W24: S4
A25: PR-01 | B25: Prongs & heads | C25: Retip prong (first prong) | D25: per prong | E25: Prong count (add'l per prong), size | F25: P | G25: 24 | H25: 50 | I25: 75 | J25: =G25*INDEX(Assumptions!$D$5:$D$7,MATCH($F25,Assumptions!$A$5:$A$7,0)) -> 27.6 | K25: =H25*INDEX(Assumptions!$D$5:$D$7,MATCH($F25,Assumptions!$A$5:$A$7,0)) -> 57.5 | L25: =I25*INDEX(Assumptions!$D$5:$D$7,MATCH($F25,Assumptions!$A$5:$A$7,0)) -> 86.25 | M25: =G25*INDEX(Assumptions!$E$5:$E$7,MATCH($F25,Assumptions!$A$5:$A$7,0)) -> 48 | N25: =H25*INDEX(Assumptions!$E$5:$E$7,MATCH($F25,Assumptions!$A$5:$A$7,0)) -> 100 | O25: =I25*INDEX(Assumptions!$E$5:$E$7,MATCH($F25,Assumptions!$A$5:$A$7,0)) -> 150 | P25: 20 | Q25: 0 | R25: 2 | S25: 5 | T25: 10 | U25: Yes | V25: Macro photo of each prong from 2 angles; count worn / missing prongs. Record center stone shape, est. carat, chips, loose stone (tap test). | W25: S1,S2,S3,S4
A26: PR-02 | B26: Prongs & heads | C26: Rebuild full prong (first prong) | D26: per prong | E26: Prong count (add'l per prong) | F26: P | G26: 22 | H26: 60 | I26: 90 | J26: =G26*INDEX(Assumptions!$D$5:$D$7,MATCH($F26,Assumptions!$A$5:$A$7,0)) -> 25.3 | K26: =H26*INDEX(Assumptions!$D$5:$D$7,MATCH($F26,Assumptions!$A$5:$A$7,0)) -> 69 | L26: =I26*INDEX(Assumptions!$D$5:$D$7,MATCH($F26,Assumptions!$A$5:$A$7,0)) -> 103.5 | M26: =G26*INDEX(Assumptions!$E$5:$E$7,MATCH($F26,Assumptions!$A$5:$A$7,0)) -> 44 | N26: =H26*INDEX(Assumptions!$E$5:$E$7,MATCH($F26,Assumptions!$A$5:$A$7,0)) -> 120 | O26: =I26*INDEX(Assumptions!$E$5:$E$7,MATCH($F26,Assumptions!$A$5:$A$7,0)) -> 180 | P26: 30 | Q26: 0 | R26: 2 | S26: 5 | T26: 10 | U26: Yes | V26: Macro photo of each prong from 2 angles; count worn / missing prongs. Record center stone shape, est. carat, chips, loose stone (tap test). | W26: S1,S2,S3
A27: PR-03 | B27: Prongs & heads | C27: Retip all prongs, 4-prong solitaire | D27: per head | E27: Center stone size, prong wear | F27: P | G27: 120 | H27: 150 | I27: 300 | J27: =G27*INDEX(Assumptions!$D$5:$D$7,MATCH($F27,Assumptions!$A$5:$A$7,0)) -> 138 | K27: =H27*INDEX(Assumptions!$D$5:$D$7,MATCH($F27,Assumptions!$A$5:$A$7,0)) -> 172.5 | L27: =I27*INDEX(Assumptions!$D$5:$D$7,MATCH($F27,Assumptions!$A$5:$A$7,0)) -> 345 | M27: =G27*INDEX(Assumptions!$E$5:$E$7,MATCH($F27,Assumptions!$A$5:$A$7,0)) -> 240 | N27: =H27*INDEX(Assumptions!$E$5:$E$7,MATCH($F27,Assumptions!$A$5:$A$7,0)) -> 300 | O27: =I27*INDEX(Assumptions!$E$5:$E$7,MATCH($F27,Assumptions!$A$5:$A$7,0)) -> 600 | Q27: 1 | R27: 3 | S27: 5 | T27: 10 | U27: No | V27: Macro photo of each prong from 2 angles; count worn / missing prongs. Record center stone shape, est. carat, chips, loose stone (tap test). | W27: S4
A28: PR-04 | B28: Prongs & heads | C28: V-prong rebuild (princess / marquise corner) | D28: per prong | E28: Prong count | F28: P | G28: 50 | H28: 60 | I28: 90 | J28: =G28*INDEX(Assumptions!$D$5:$D$7,MATCH($F28,Assumptions!$A$5:$A$7,0)) -> 57.5 | K28: =H28*INDEX(Assumptions!$D$5:$D$7,MATCH($F28,Assumptions!$A$5:$A$7,0)) -> 69 | L28: =I28*INDEX(Assumptions!$D$5:$D$7,MATCH($F28,Assumptions!$A$5:$A$7,0)) -> 103.5 | M28: =G28*INDEX(Assumptions!$E$5:$E$7,MATCH($F28,Assumptions!$A$5:$A$7,0)) -> 100 | N28: =H28*INDEX(Assumptions!$E$5:$E$7,MATCH($F28,Assumptions!$A$5:$A$7,0)) -> 120 | O28: =I28*INDEX(Assumptions!$E$5:$E$7,MATCH($F28,Assumptions!$A$5:$A$7,0)) -> 180 | P28: 25 | Q28: 1 | R28: 3 | S28: 5 | T28: 10 | U28: No | V28: Macro photo of each prong from 2 angles; count worn / missing prongs. Record center stone shape, est. carat, chips, loose stone (tap test). | W28: S1
A29: PR-05 | B29: Prongs & heads | C29: Straighten / smooth prongs and refinish | D29: per ring | E29: Prong count | F29: L | G29: 40 | H29: 50 | I29: 75 | J29: =G29*INDEX(Assumptions!$D$5:$D$7,MATCH($F29,Assumptions!$A$5:$A$7,0)) -> 40 | K29: =H29*INDEX(Assumptions!$D$5:$D$7,MATCH($F29,Assumptions!$A$5:$A$7,0)) -> 50 | L29: =I29*INDEX(Assumptions!$D$5:$D$7,MATCH($F29,Assumptions!$A$5:$A$7,0)) -> 75 | M29: =G29*INDEX(Assumptions!$E$5:$E$7,MATCH($F29,Assumptions!$A$5:$A$7,0)) -> 48 | N29: =H29*INDEX(Assumptions!$E$5:$E$7,MATCH($F29,Assumptions!$A$5:$A$7,0)) -> 60 | O29: =I29*INDEX(Assumptions!$E$5:$E$7,MATCH($F29,Assumptions!$A$5:$A$7,0)) -> 90 | Q29: 0 | R29: 1 | S29: 3 | T29: 7 | U29: Yes | V29: Macro photo of each prong from 2 angles; count worn / missing prongs. Record center stone shape, est. carat, chips, loose stone (tap test). | W29: S1
A30: PR-06 | B30: Prongs & heads | C30: Replace head and reset center, .01 to .25ct | D30: per head | E30: Carat, shape (fancy +15%) | F30: P | G30: 95 | H30: 110 | I30: 160 | J30: =G30*INDEX(Assumptions!$D$5:$D$7,MATCH($F30,Assumptions!$A$5:$A$7,0)) -> 109.25 | K30: =H30*INDEX(Assumptions!$D$5:$D$7,MATCH($F30,Assumptions!$A$5:$A$7,0)) -> 126.5 | L30: =I30*INDEX(Assumptions!$D$5:$D$7,MATCH($F30,Assumptions!$A$5:$A$7,0)) -> 184 | M30: =G30*INDEX(Assumptions!$E$5:$E$7,MATCH($F30,Assumptions!$A$5:$A$7,0)) -> 190 | N30: =H30*INDEX(Assumptions!$E$5:$E$7,MATCH($F30,Assumptions!$A$5:$A$7,0)) -> 220 | O30: =I30*INDEX(Assumptions!$E$5:$E$7,MATCH($F30,Assumptions!$A$5:$A$7,0)) -> 320 | Q30: 1 | R30: 3 | S30: 7 | T30: 15 | U30: No | V30: Macro photo of each prong from 2 angles; count worn / missing prongs. Record center stone shape, est. carat, chips, loose stone (tap test). | W30: S1
A31: PR-07 | B31: Prongs & heads | C31: Replace head and reset center, .26 to .50ct | D31: per head | E31: Carat, shape (fancy +15%) | F31: P | G31: 125 | H31: 150 | I31: 220 | J31: =G31*INDEX(Assumptions!$D$5:$D$7,MATCH($F31,Assumptions!$A$5:$A$7,0)) -> 143.75 | K31: =H31*INDEX(Assumptions!$D$5:$D$7,MATCH($F31,Assumptions!$A$5:$A$7,0)) -> 172.5 | L31: =I31*INDEX(Assumptions!$D$5:$D$7,MATCH($F31,Assumptions!$A$5:$A$7,0)) -> 253 | M31: =G31*INDEX(Assumptions!$E$5:$E$7,MATCH($F31,Assumptions!$A$5:$A$7,0)) -> 250 | N31: =H31*INDEX(Assumptions!$E$5:$E$7,MATCH($F31,Assumptions!$A$5:$A$7,0)) -> 300 | O31: =I31*INDEX(Assumptions!$E$5:$E$7,MATCH($F31,Assumptions!$A$5:$A$7,0)) -> 440 | Q31: 1 | R31: 5 | S31: 7 | T31: 15 | U31: No | V31: Macro photo of each prong from 2 angles; count worn / missing prongs. Record center stone shape, est. carat, chips, loose stone (tap test). | W31: S1
A32: PR-08 | B32: Prongs & heads | C32: Replace head and reset center, .51 to 1.00ct | D32: per head | E32: Carat, shape (fancy +15%) | F32: P | G32: 170 | H32: 190 | I32: 260 | J32: =G32*INDEX(Assumptions!$D$5:$D$7,MATCH($F32,Assumptions!$A$5:$A$7,0)) -> 195.5 | K32: =H32*INDEX(Assumptions!$D$5:$D$7,MATCH($F32,Assumptions!$A$5:$A$7,0)) -> 218.5 | L32: =I32*INDEX(Assumptions!$D$5:$D$7,MATCH($F32,Assumptions!$A$5:$A$7,0)) -> 299 | M32: =G32*INDEX(Assumptions!$E$5:$E$7,MATCH($F32,Assumptions!$A$5:$A$7,0)) -> 340 | N32: =H32*INDEX(Assumptions!$E$5:$E$7,MATCH($F32,Assumptions!$A$5:$A$7,0)) -> 380 | O32: =I32*INDEX(Assumptions!$E$5:$E$7,MATCH($F32,Assumptions!$A$5:$A$7,0)) -> 520 | Q32: 1 | R32: 5 | S32: 7 | T32: 15 | U32: No | V32: Macro photo of each prong from 2 angles; count worn / missing prongs. Record center stone shape, est. carat, chips, loose stone (tap test). | W32: S1
A33: PR-09 | B33: Prongs & heads | C33: Replace head and reset center, 1.01 to 2.00ct | D33: per head | E33: Carat, shape (fancy +15%) | F33: P | G33: 200 | H33: 230 | I33: 320 | J33: =G33*INDEX(Assumptions!$D$5:$D$7,MATCH($F33,Assumptions!$A$5:$A$7,0)) -> 230 | K33: =H33*INDEX(Assumptions!$D$5:$D$7,MATCH($F33,Assumptions!$A$5:$A$7,0)) -> 264.5 | L33: =I33*INDEX(Assumptions!$D$5:$D$7,MATCH($F33,Assumptions!$A$5:$A$7,0)) -> 368 | M33: =G33*INDEX(Assumptions!$E$5:$E$7,MATCH($F33,Assumptions!$A$5:$A$7,0)) -> 400 | N33: =H33*INDEX(Assumptions!$E$5:$E$7,MATCH($F33,Assumptions!$A$5:$A$7,0)) -> 460 | O33: =I33*INDEX(Assumptions!$E$5:$E$7,MATCH($F33,Assumptions!$A$5:$A$7,0)) -> 640 | Q33: 2 | R33: 5 | S33: 7 | T33: 15 | U33: No | V33: Macro photo of each prong from 2 angles; count worn / missing prongs. Record center stone shape, est. carat, chips, loose stone (tap test). | W33: S1
A34: PR-10 | B34: Prongs & heads | C34: Straighten / lower / reinstall head | D34: per head | E34: Head style | F34: P | G34: 45 | H34: 50 | I34: 80 | J34: =G34*INDEX(Assumptions!$D$5:$D$7,MATCH($F34,Assumptions!$A$5:$A$7,0)) -> 51.75 | K34: =H34*INDEX(Assumptions!$D$5:$D$7,MATCH($F34,Assumptions!$A$5:$A$7,0)) -> 57.5 | L34: =I34*INDEX(Assumptions!$D$5:$D$7,MATCH($F34,Assumptions!$A$5:$A$7,0)) -> 92 | M34: =G34*INDEX(Assumptions!$E$5:$E$7,MATCH($F34,Assumptions!$A$5:$A$7,0)) -> 90 | N34: =H34*INDEX(Assumptions!$E$5:$E$7,MATCH($F34,Assumptions!$A$5:$A$7,0)) -> 100 | O34: =I34*INDEX(Assumptions!$E$5:$E$7,MATCH($F34,Assumptions!$A$5:$A$7,0)) -> 160 | Q34: 0 | R34: 2 | S34: 5 | T34: 10 | U34: Yes | V34: Macro photo of each prong from 2 angles; count worn / missing prongs. Record center stone shape, est. carat, chips, loose stone (tap test). | W34: S1
A35: ST-01 | B35: Stones | C35: Tighten center stone (incl. refinish) | D35: per ring | E35: Setting type | F35: L | G35: 34 | H35: 65 | I35: 90 | J35: =G35*INDEX(Assumptions!$D$5:$D$7,MATCH($F35,Assumptions!$A$5:$A$7,0)) -> 34 | K35: =H35*INDEX(Assumptions!$D$5:$D$7,MATCH($F35,Assumptions!$A$5:$A$7,0)) -> 65 | L35: =I35*INDEX(Assumptions!$D$5:$D$7,MATCH($F35,Assumptions!$A$5:$A$7,0)) -> 90 | M35: =G35*INDEX(Assumptions!$E$5:$E$7,MATCH($F35,Assumptions!$A$5:$A$7,0)) -> 40.8 | N35: =H35*INDEX(Assumptions!$E$5:$E$7,MATCH($F35,Assumptions!$A$5:$A$7,0)) -> 78 | O35: =I35*INDEX(Assumptions!$E$5:$E$7,MATCH($F35,Assumptions!$A$5:$A$7,0)) -> 108 | Q35: 0 | R35: 1 | S35: 5 | T35: 7 | U35: Yes | V35: Macro photo of every stone; mark missing / chipped / loose on a ring map. Record stone type, est. size, setting style. Flag heat-sensitive stones (emerald, opal, tanzanite, pearl). | W35: S1,S2,S3,S5
A36: ST-02 | B36: Stones | C36: Tighten side / accent stones (first stone) | D36: per stone | E36: Stone count (add'l per stone) | F36: L | G36: 34 | H36: 55 | I36: 75 | J36: =G36*INDEX(Assumptions!$D$5:$D$7,MATCH($F36,Assumptions!$A$5:$A$7,0)) -> 34 | K36: =H36*INDEX(Assumptions!$D$5:$D$7,MATCH($F36,Assumptions!$A$5:$A$7,0)) -> 55 | L36: =I36*INDEX(Assumptions!$D$5:$D$7,MATCH($F36,Assumptions!$A$5:$A$7,0)) -> 75 | M36: =G36*INDEX(Assumptions!$E$5:$E$7,MATCH($F36,Assumptions!$A$5:$A$7,0)) -> 40.8 | N36: =H36*INDEX(Assumptions!$E$5:$E$7,MATCH($F36,Assumptions!$A$5:$A$7,0)) -> 66 | O36: =I36*INDEX(Assumptions!$E$5:$E$7,MATCH($F36,Assumptions!$A$5:$A$7,0)) -> 90 | P36: 20 | Q36: 0 | R36: 1 | S36: 5 | T36: 7 | U36: Yes | V36: Macro photo of every stone; mark missing / chipped / loose on a ring map. Record stone type, est. size, setting style. Flag heat-sensitive stones (emerald, opal, tanzanite, pearl). | W36: S1,S2,S4
A37: ST-03 | B37: Stones | C37: Tighten channel / baguette stones (first stone) | D37: per stone | E37: Stone count (add'l per stone) | F37: L | G37: 45 | H37: 55 | I37: 80 | J37: =G37*INDEX(Assumptions!$D$5:$D$7,MATCH($F37,Assumptions!$A$5:$A$7,0)) -> 45 | K37: =H37*INDEX(Assumptions!$D$5:$D$7,MATCH($F37,Assumptions!$A$5:$A$7,0)) -> 55 | L37: =I37*INDEX(Assumptions!$D$5:$D$7,MATCH($F37,Assumptions!$A$5:$A$7,0)) -> 80 | M37: =G37*INDEX(Assumptions!$E$5:$E$7,MATCH($F37,Assumptions!$A$5:$A$7,0)) -> 54 | N37: =H37*INDEX(Assumptions!$E$5:$E$7,MATCH($F37,Assumptions!$A$5:$A$7,0)) -> 66 | O37: =I37*INDEX(Assumptions!$E$5:$E$7,MATCH($F37,Assumptions!$A$5:$A$7,0)) -> 96 | P37: 15 | Q37: 0 | R37: 2 | S37: 5 | T37: 7 | U37: Yes | V37: Macro photo of every stone; mark missing / chipped / loose on a ring map. Record stone type, est. size, setting style. Flag heat-sensitive stones (emerald, opal, tanzanite, pearl). | W37: S1
A38: ST-04 | B38: Stones | C38: Tighten bezel-set stone (first stone) | D38: per stone | E38: Stone count (add'l per stone) | F38: L | G38: 50 | H38: 65 | I38: 90 | J38: =G38*INDEX(Assumptions!$D$5:$D$7,MATCH($F38,Assumptions!$A$5:$A$7,0)) -> 50 | K38: =H38*INDEX(Assumptions!$D$5:$D$7,MATCH($F38,Assumptions!$A$5:$A$7,0)) -> 65 | L38: =I38*INDEX(Assumptions!$D$5:$D$7,MATCH($F38,Assumptions!$A$5:$A$7,0)) -> 90 | M38: =G38*INDEX(Assumptions!$E$5:$E$7,MATCH($F38,Assumptions!$A$5:$A$7,0)) -> 60 | N38: =H38*INDEX(Assumptions!$E$5:$E$7,MATCH($F38,Assumptions!$A$5:$A$7,0)) -> 78 | O38: =I38*INDEX(Assumptions!$E$5:$E$7,MATCH($F38,Assumptions!$A$5:$A$7,0)) -> 108 | P38: 25 | Q38: 0 | R38: 2 | S38: 5 | T38: 7 | U38: Yes | V38: Macro photo of every stone; mark missing / chipped / loose on a ring map. Record stone type, est. size, setting style. Flag heat-sensitive stones (emerald, opal, tanzanite, pearl). | W38: S1
A39: ST-05 | B39: Stones | C39: Set stone up to .10ct (labor; stone extra) | D39: per stone | E39: Carat, shape (fancy +15%), bezel +20% | F39: L | G39: 15 | H39: 50 | I39: 60 | J39: =G39*INDEX(Assumptions!$D$5:$D$7,MATCH($F39,Assumptions!$A$5:$A$7,0)) -> 15 | K39: =H39*INDEX(Assumptions!$D$5:$D$7,MATCH($F39,Assumptions!$A$5:$A$7,0)) -> 50 | L39: =I39*INDEX(Assumptions!$D$5:$D$7,MATCH($F39,Assumptions!$A$5:$A$7,0)) -> 60 | M39: =G39*INDEX(Assumptions!$E$5:$E$7,MATCH($F39,Assumptions!$A$5:$A$7,0)) -> 18 | N39: =H39*INDEX(Assumptions!$E$5:$E$7,MATCH($F39,Assumptions!$A$5:$A$7,0)) -> 60 | O39: =I39*INDEX(Assumptions!$E$5:$E$7,MATCH($F39,Assumptions!$A$5:$A$7,0)) -> 72 | Q39: 0 | R39: 2 | S39: 5 | T39: 10 | U39: Yes | V39: Macro photo of every stone; mark missing / chipped / loose on a ring map. Record stone type, est. size, setting style. Flag heat-sensitive stones (emerald, opal, tanzanite, pearl). | W39: S1,S2,S3
A40: ST-06 | B40: Stones | C40: Set stone .11 to .25ct (labor; stone extra) | D40: per stone | E40: Carat, shape, setting style | F40: L | G40: 50 | H40: 58 | I40: 80 | J40: =G40*INDEX(Assumptions!$D$5:$D$7,MATCH($F40,Assumptions!$A$5:$A$7,0)) -> 50 | K40: =H40*INDEX(Assumptions!$D$5:$D$7,MATCH($F40,Assumptions!$A$5:$A$7,0)) -> 58 | L40: =I40*INDEX(Assumptions!$D$5:$D$7,MATCH($F40,Assumptions!$A$5:$A$7,0)) -> 80 | M40: =G40*INDEX(Assumptions!$E$5:$E$7,MATCH($F40,Assumptions!$A$5:$A$7,0)) -> 60 | N40: =H40*INDEX(Assumptions!$E$5:$E$7,MATCH($F40,Assumptions!$A$5:$A$7,0)) -> 69.6 | O40: =I40*INDEX(Assumptions!$E$5:$E$7,MATCH($F40,Assumptions!$A$5:$A$7,0)) -> 96 | Q40: 0 | R40: 2 | S40: 5 | T40: 10 | U40: Yes | V40: Macro photo of every stone; mark missing / chipped / loose on a ring map. Record stone type, est. size, setting style. Flag heat-sensitive stones (emerald, opal, tanzanite, pearl). | W40: S1
...

Sheet Estimator
A1: Repair Estimator (test harness for engine logic)
A2: Edit the yellow cells. Everything else is calculated from the Service Catalog and Assumptions.
A4: Service code | B4: PR-01
A5: Metal | B5: Platinum
A6: Additional units (extra prongs, stones, sizes) | B6: 3
A7: White gold item? | B7: No
A8: Rush? | B8: No
A10: Result
A11: Service | B11: =INDEX('Service Catalog'!$C$5:$C$76,MATCH($B$4,'Service Catalog'!$A$5:$A$76,0)) -> Retip prong (first prong)
A12: Unit | B12: =INDEX('Service Catalog'!$D$5:$D$76,MATCH($B$4,'Service Catalog'!$A$5:$A$76,0)) -> per prong
A13: Metal class | B13: =INDEX('Service Catalog'!$F$5:$F$76,MATCH($B$4,'Service Catalog'!$A$5:$A$76,0)) -> P
A14: Metal multiplier | B14: =INDEX(Assumptions!$C$5:$E$7,MATCH(B13,Assumptions!$A$5:$A$7,0),MATCH($B$5,Assumptions!$C$4:$E$4,0)) -> 2
A15: Add-ons (add'l units + white gold + rush) | B15: =$B$6*INDEX('Service Catalog'!$P$5:$P$76,MATCH($B$4,'Service Catalog'!$A$5:$A$76,0))*B14+IF(AND($B$7="Yes",$B$5<>"Platinum"),Assumptions!$C$10,0)+IF($B$8="Yes",Assumptions!$C$11,0) -> 120
A16: Estimate: low | B16: =INDEX('Service Catalog'!$G$5:$O$76,MATCH($B$4,'Service Catalog'!$A$5:$A$76,0),(MATCH($B$5,Assumptions!$C$4:$E$4,0)-1)*3+1)+B15 -> 168
A17: Estimate: typical | B17: =INDEX('Service Catalog'!$G$5:$O$76,MATCH($B$4,'Service Catalog'!$A$5:$A$76,0),(MATCH($B$5,Assumptions!$C$4:$E$4,0)-1)*3+2)+B15 -> 220
A18: Estimate: high | B18: =INDEX('Service Catalog'!$G$5:$O$76,MATCH($B$4,'Service Catalog'!$A$5:$A$76,0),(MATCH($B$5,Assumptions!$C$4:$E$4,0)-1)*3+3)+B15 -> 270
A19: Turnaround in-house | B19: =IF(INDEX('Service Catalog'!$R$5:$R$76,MATCH($B$4,'Service Catalog'!$A$5:$A$76,0))="","n/a",IF($B$8="Yes","Same day / next day",INDEX('Service Catalog'!$Q$5:$Q$76,MATCH($B$4,'Service Catalog'!$A$5:$A$76,0))&" to "&INDEX('Service Catalog'!$R$5:$R$76,MATCH($B$4,'Service Catalog'!$A$5:$A$76,0))&" business days")) -> 0 to 2 business days
A20: Turnaround sent out | B20: =IF(INDEX('Service Catalog'!$T$5:$T$76,MATCH($B$4,'Service Catalog'!$A$5:$A$76,0))="","n/a",INDEX('Service Catalog'!$S$5:$S$76,MATCH($B$4,'Service Catalog'!$A$5:$A$76,0))&" to "&INDEX('Service Catalog'!$T$5:$T$76,MATCH($B$4,'Service Catalog'!$A$5:$A$76,0))&" business days") -> 5 to 10 business days
A21: Same-day eligible | B21: =INDEX('Service Catalog'!$U$5:$U$76,MATCH($B$4,'Service Catalog'!$A$5:$A$76,0)) -> Yes
A22: Intake checklist | B22: =INDEX('Service Catalog'!$V$5:$V$76,MATCH($B$4,'Service Catalog'!$A$5:$A$76,0)) -> Macro photo of each prong from 2 angles; count worn / missing prongs. Record center stone shape, est. carat, chips, loose stone (tap test).
A24: Example: platinum solitaire with 4 worn prongs = PR-01 (first prong) + 3 additional units.

Sheet Sources
A1: Code | B1: Source | C1: Used for | D1: URL
A2: S1 | B2: Expert Jewelry Repair & Design, repair price list (Appleton, WI) | C2: Most complete line-item list; 18K +20%, platinum 3x, head and setting tables by carat | D2: https://www.jewelercam.com/repair-price-list/
A3: S2 | B3: My Jewelry Repair, pricing page | C3: Ring repair, sizing, shank, stone, engraving prices | D3: https://myjewelryrepair.com/pricing/
A4: S3 | B4: Quick Jewelry Repairs, pricing (updated July 2020) | C4: Low-end benchmarks: sizing, chain, prongs, plating, appraisal | D4: https://quickjewelryrepairs.com/pricing/
A5: S4 | B5: Robinson's Jewelers, Common jewelry repairs and costs in 2025 | C5: Ranges for sizing, prongs, chains, shanks, earrings, cleaning | D5: https://robinsonsjewelers.com/blogs/news/common-jewelry-repairs-how-much-they-cost-in-2025-your-guide-to-a-sparkling-comeback
A6: S5 | B6: MoissaniteCo, jewelry repair price list | C6: Gold vs platinum differentials (polish, tightening, solder) | D6: https://www.moissaniteco.com/jewelry-repair-side-stone-price-list
A7: S6 | B7: SVS Fine Jewelry, in-house repair (Long Island) | C7: In-house same-day services; stone sourcing up to 4 weeks | D7: https://www.svsfinejewelry.com/pages/jewelry-repair
A8: S7 | B8: Stonebridge Jewelry, fine jewelry repair turnaround guide | C8: Turnaround by repair type; mail-in 2 to 8 weeks | D8: https://stonebridgejewelry.com/blog/fine-jewelry-repair-turnaround-time-guide
A9: S8 | B9: Kay Jewelers mail-in repair FAQ | C9: Chain mail-in benchmark: most simple repairs within 10 days | D9: https://jewelryrepairdirect.com/pages/faq
A10: S9 | B10: InStore: How David Geller figures repair pricing | C10: Method: per-task labor plus materials ~3x cost; metal tied to spot | D10: https://instoremag.com/here-s-how-shop-expert-david-geller-figures-repair-pricing/
A11: Ref | B11: Geller's Blue Book to Jewelry Repair & Design (paid guide, not reproduced) | C11: Industry-standard reference; buy a license to calibrate | D11: https://www.jewelerprofit.com/Blue_Book.html
